const x = 10

try {

} catch(err) {
    
}